{"name": "Проверяем получение списка пользователей", "status": "broken", "statusDetails": {"message": "httpx.ConnectTimeout: _ssl.c:1003: The handshake operation timed out", "trace": "@contextlib.contextmanager\n    def map_httpcore_exceptions() -> typing.Iterator[None]:\n        global HTTPCORE_EXC_MAP\n        if len(HTTPCORE_EXC_MAP) == 0:\n            HTTPCORE_EXC_MAP = _load_httpcore_exceptions()\n        try:\n>           yield\n\n..\\..\\AppData\\Local\\Programs\\Python\\Python313\\Lib\\site-packages\\httpx\\_transports\\default.py:101: \n_ _ _ _ _ _ _ _ _ _ _ _ _ _ _ _ _ _ _ _ _ _ _ _ _ _ _ _ _ _ _ _ _ _ _ _ _ _ _ _\n..\\..\\AppData\\Local\\Programs\\Python\\Python313\\Lib\\site-packages\\httpx\\_transports\\default.py:250: in handle_request\n    resp = self._pool.handle_request(req)\n..\\..\\AppData\\Local\\Programs\\Python\\Python313\\Lib\\site-packages\\httpcore\\_sync\\connection_pool.py:256: in handle_request\n    raise exc from None\n..\\..\\AppData\\Local\\Programs\\Python\\Python313\\Lib\\site-packages\\httpcore\\_sync\\connection_pool.py:236: in handle_request\n    response = connection.handle_request(\n..\\..\\AppData\\Local\\Programs\\Python\\Python313\\Lib\\site-packages\\httpcore\\_sync\\connection.py:101: in handle_request\n    raise exc\n..\\..\\AppData\\Local\\Programs\\Python\\Python313\\Lib\\site-packages\\httpcore\\_sync\\connection.py:78: in handle_request\n    stream = self._connect(request)\n..\\..\\AppData\\Local\\Programs\\Python\\Python313\\Lib\\site-packages\\httpcore\\_sync\\connection.py:156: in _connect\n    stream = stream.start_tls(**kwargs)\n..\\..\\AppData\\Local\\Programs\\Python\\Python313\\Lib\\site-packages\\httpcore\\_backends\\sync.py:154: in start_tls\n    with map_exceptions(exc_map):\n..\\..\\AppData\\Local\\Programs\\Python\\Python313\\Lib\\contextlib.py:162: in __exit__\n    self.gen.throw(value)\n_ _ _ _ _ _ _ _ _ _ _ _ _ _ _ _ _ _ _ _ _ _ _ _ _ _ _ _ _ _ _ _ _ _ _ _ _ _ _ _\n\nmap = {<class 'TimeoutError'>: <class 'httpcore.ConnectTimeout'>, <class 'OSError'>: <class 'httpcore.ConnectError'>}\n\n    @contextlib.contextmanager\n    def map_exceptions(map: ExceptionMapping) -> typing.Iterator[None]:\n        try:\n            yield\n        except Exception as exc:  # noqa: PIE786\n            for from_exc, to_exc in map.items():\n                if isinstance(exc, from_exc):\n>                   raise to_exc(exc) from exc\nE                   httpcore.ConnectTimeout: _ssl.c:1003: The handshake operation timed out\n\n..\\..\\AppData\\Local\\Programs\\Python\\Python313\\Lib\\site-packages\\httpcore\\_exceptions.py:14: ConnectTimeout\n\nThe above exception was the direct cause of the following exception:\n\n    @allure.suite('Проверка запросов данных пользователей')\n    @allure.title('Проверяем получение списка пользователей')\n    def test_list_users():\n        with allure.step(f'Делаем запрос по адресу: {BASE_URL + LIST_USERS}'):\n>           response = httpx.get(BASE_URL + LIST_USERS)\n\ntests\\test_get_user_data.py:17: \n_ _ _ _ _ _ _ _ _ _ _ _ _ _ _ _ _ _ _ _ _ _ _ _ _ _ _ _ _ _ _ _ _ _ _ _ _ _ _ _\n..\\..\\AppData\\Local\\Programs\\Python\\Python313\\Lib\\site-packages\\httpx\\_api.py:195: in get\n    return request(\n..\\..\\AppData\\Local\\Programs\\Python\\Python313\\Lib\\site-packages\\httpx\\_api.py:109: in request\n    return client.request(\n..\\..\\AppData\\Local\\Programs\\Python\\Python313\\Lib\\site-packages\\httpx\\_client.py:825: in request\n    return self.send(request, auth=auth, follow_redirects=follow_redirects)\n..\\..\\AppData\\Local\\Programs\\Python\\Python313\\Lib\\site-packages\\httpx\\_client.py:914: in send\n    response = self._send_handling_auth(\n..\\..\\AppData\\Local\\Programs\\Python\\Python313\\Lib\\site-packages\\httpx\\_client.py:942: in _send_handling_auth\n    response = self._send_handling_redirects(\n..\\..\\AppData\\Local\\Programs\\Python\\Python313\\Lib\\site-packages\\httpx\\_client.py:979: in _send_handling_redirects\n    response = self._send_single_request(request)\n..\\..\\AppData\\Local\\Programs\\Python\\Python313\\Lib\\site-packages\\httpx\\_client.py:1014: in _send_single_request\n    response = transport.handle_request(request)\n..\\..\\AppData\\Local\\Programs\\Python\\Python313\\Lib\\site-packages\\httpx\\_transports\\default.py:249: in handle_request\n    with map_httpcore_exceptions():\n..\\..\\AppData\\Local\\Programs\\Python\\Python313\\Lib\\contextlib.py:162: in __exit__\n    self.gen.throw(value)\n_ _ _ _ _ _ _ _ _ _ _ _ _ _ _ _ _ _ _ _ _ _ _ _ _ _ _ _ _ _ _ _ _ _ _ _ _ _ _ _\n\n    @contextlib.contextmanager\n    def map_httpcore_exceptions() -> typing.Iterator[None]:\n        global HTTPCORE_EXC_MAP\n        if len(HTTPCORE_EXC_MAP) == 0:\n            HTTPCORE_EXC_MAP = _load_httpcore_exceptions()\n        try:\n            yield\n        except Exception as exc:\n            mapped_exc = None\n    \n            for from_exc, to_exc in HTTPCORE_EXC_MAP.items():\n                if not isinstance(exc, from_exc):\n                    continue\n                # We want to map to the most specific exception we can find.\n                # Eg if `exc` is an `httpcore.ReadTimeout`, we want to map to\n                # `httpx.ReadTimeout`, not just `httpx.TimeoutException`.\n                if mapped_exc is None or issubclass(to_exc, mapped_exc):\n                    mapped_exc = to_exc\n    \n            if mapped_exc is None:  # pragma: no cover\n                raise\n    \n            message = str(exc)\n>           raise mapped_exc(message) from exc\nE           httpx.ConnectTimeout: _ssl.c:1003: The handshake operation timed out\n\n..\\..\\AppData\\Local\\Programs\\Python\\Python313\\Lib\\site-packages\\httpx\\_transports\\default.py:118: ConnectTimeout"}, "steps": [{"name": "Делаем запрос по адресу: https://reqres.in/api/users?page=2", "status": "broken", "statusDetails": {"message": "httpx.ConnectTimeout: _ssl.c:1003: The handshake operation timed out\n", "trace": "  File \"C:\\Users\\User\\PycharmProjects\\ApiTests\\tests\\test_get_user_data.py\", line 17, in test_list_users\n    response = httpx.get(BASE_URL + LIST_USERS)\n  File \"C:\\Users\\User\\AppData\\Local\\Programs\\Python\\Python313\\Lib\\site-packages\\httpx\\_api.py\", line 195, in get\n    return request(\n        \"GET\",\n    ...<9 lines>...\n        trust_env=trust_env,\n    )\n  File \"C:\\Users\\User\\AppData\\Local\\Programs\\Python\\Python313\\Lib\\site-packages\\httpx\\_api.py\", line 109, in request\n    return client.request(\n           ~~~~~~~~~~~~~~^\n        method=method,\n        ^^^^^^^^^^^^^^\n    ...<8 lines>...\n        follow_redirects=follow_redirects,\n        ^^^^^^^^^^^^^^^^^^^^^^^^^^^^^^^^^^\n    )\n    ^\n  File \"C:\\Users\\User\\AppData\\Local\\Programs\\Python\\Python313\\Lib\\site-packages\\httpx\\_client.py\", line 825, in request\n    return self.send(request, auth=auth, follow_redirects=follow_redirects)\n           ~~~~~~~~~^^^^^^^^^^^^^^^^^^^^^^^^^^^^^^^^^^^^^^^^^^^^^^^^^^^^^^^\n  File \"C:\\Users\\User\\AppData\\Local\\Programs\\Python\\Python313\\Lib\\site-packages\\httpx\\_client.py\", line 914, in send\n    response = self._send_handling_auth(\n        request,\n    ...<2 lines>...\n        history=[],\n    )\n  File \"C:\\Users\\User\\AppData\\Local\\Programs\\Python\\Python313\\Lib\\site-packages\\httpx\\_client.py\", line 942, in _send_handling_auth\n    response = self._send_handling_redirects(\n        request,\n        follow_redirects=follow_redirects,\n        history=history,\n    )\n  File \"C:\\Users\\User\\AppData\\Local\\Programs\\Python\\Python313\\Lib\\site-packages\\httpx\\_client.py\", line 979, in _send_handling_redirects\n    response = self._send_single_request(request)\n  File \"C:\\Users\\User\\AppData\\Local\\Programs\\Python\\Python313\\Lib\\site-packages\\httpx\\_client.py\", line 1014, in _send_single_request\n    response = transport.handle_request(request)\n  File \"C:\\Users\\User\\AppData\\Local\\Programs\\Python\\Python313\\Lib\\site-packages\\httpx\\_transports\\default.py\", line 249, in handle_request\n    with map_httpcore_exceptions():\n         ~~~~~~~~~~~~~~~~~~~~~~~^^\n  File \"C:\\Users\\User\\AppData\\Local\\Programs\\Python\\Python313\\Lib\\contextlib.py\", line 162, in __exit__\n    self.gen.throw(value)\n    ~~~~~~~~~~~~~~^^^^^^^\n  File \"C:\\Users\\User\\AppData\\Local\\Programs\\Python\\Python313\\Lib\\site-packages\\httpx\\_transports\\default.py\", line 118, in map_httpcore_exceptions\n    raise mapped_exc(message) from exc\n"}, "start": 1736267881209, "stop": 1736267896581}], "start": 1736267881208, "stop": 1736267896590, "uuid": "81bfe2b1-6854-43b1-ba2f-8ff258e3cf92", "historyId": "ba4e741c79b7ce1d9e5fd53d305486ec", "testCaseId": "ba4e741c79b7ce1d9e5fd53d305486ec", "fullName": "tests.test_get_user_data#test_list_users", "labels": [{"name": "suite", "value": "Проверка запросов данных пользователей"}, {"name": "parentSuite", "value": "tests"}, {"name": "host", "value": "WIN-L0M9L8LCB9P"}, {"name": "thread", "value": "11696-MainThread"}, {"name": "framework", "value": "pytest"}, {"name": "language", "value": "cpython3"}, {"name": "package", "value": "tests.test_get_user_data"}]}